<?xml version="1.0" ?>
<!-- =================================================================================== -->
<!-- |    This document was autogenerated by xacro from up1.xacro                      | -->
<!-- |    EDITING THIS FILE BY HAND IS NOT RECOMMENDED                                 | -->
<!-- =================================================================================== -->
<robot name="up1" xmlns:xacro="http://www.ros.org/wiki/xacro">
  <!-- This syntax does not appear to work, even in ros-indigo -->
  <!-- <xacro:arg name="manipulator_module" default="dual_arm" />
  <xacro:arg name="base_module" default="base" />
  <xacro:arg name="io_module" default="io" /> -->
  <!-- ============================   Common   ============================ -->
  <material name="black">
    <color rgba="0 0 0 1"/>
  </material>
  <material name="white">
    <color rgba="1 1 1 1"/>
  </material>
  <material name="red">
    <color rgba="1 0 0 1"/>
  </material>
  <material name="grey">
    <color rgba=".5 .5 .5 1"/>
  </material>
  <material name="green">
    <color rgba="0 1 0 1"/>
  </material>
  <material name="blue">
    <color rgba="0 0 1 1"/>
  </material>
  <material name="yellow">
    <color rgba="1 1 0 1"/>
  </material>
  <gazebo>
    <plugin filename="libgazebo_ros_control.so" name="gazebo_ros_control">
      <robotNamespace>/up1</robotNamespace>
      <robotSimType>gazebo_ros_control/DefaultRobotHWSim</robotSimType>
    </plugin>
  </gazebo>
  <!-- ============================   Base Module   ============================ -->
  <!-- base_footprint is a fictitious link(frame) that is on the ground right below base_link origin,
         navigation stack dedpends on this frame -->
  <link name="up1_footprint">
    <visual>
      <origin rpy="0 0 0" xyz="0 0 0"/>
      <geometry>
        <box size="0.01 0.01 0.01"/>
      </geometry>
      <material name="white"/>
    </visual>
    <collision>
      <origin rpy="0 0 0" xyz="0 0 0"/>
      <geometry>
        <box size="0.001 0.001 0.001"/>
      </geometry>
    </collision>
  </link>
  <joint name="up1_footprint_joint" type="fixed">
    <origin rpy="0 0 0" xyz="0 0 0.06016"/>
    <child link="base_link"/>
    <parent link="up1_footprint"/>
  </joint>
  <!-- Base Link -->
  <link name="base_link">
    <visual>
      <geometry>
        <mesh filename="package://up1_description/meshes/base/base_viz.dae" scale="0.001 0.001 0.001"/>
      </geometry>
      <material name="grey"/>
    </visual>
    <collision>
      <geometry>
        <mesh filename="package://up1_description/meshes/base/base.dae" scale="0.001 0.001 0.001"/>
      </geometry>
    </collision>
    <inertial>
      <mass value="0.30813"/>
      <inertia ixx="0.00175941073" ixy="0.00000172768" ixz="-0.00008279443" iyy="0.00172024238" iyz="0.00000045789" izz="0.00311278092"/>
    </inertial>
  </link>
  <!-- ============================   Base Module Gazebo   ============================ -->
  <gazebo>
    <plugin filename="libgazebo_ros_skid_steer_drive.so" name="skid_steer_drive_controller">
      <updateRate>100.0</updateRate>
      <robotNamespace/>
      <leftFrontJoint>base_to_left_front_wheel</leftFrontJoint>
      <rightFrontJoint>base_to_right_front_wheel</rightFrontJoint>
      <leftRearJoint>base_to_left_back_wheel</leftRearJoint>
      <rightRearJoint>base_to_right_back_wheel</rightRearJoint>
      <wheelSeparation>0.2794</wheelSeparation>
      <wheelDiameter>0.0625</wheelDiameter>
      <robotBaseFrame>up1_footprint</robotBaseFrame>
      <torque>20</torque>
      <topicName>cmd_vel</topicName>
      <broadcastTF>false</broadcastTF>
    </plugin>
  </gazebo>
  <!-- ============================   Wheel   ============================ -->
  <!-- Front Wheel Joint -->
  <joint name="base_to_right_front_wheel" type="continuous">
    <parent link="base_link"/>
    <child link="right_front_wheel"/>
    <origin rpy="1.570795 0 0" xyz="0.05569 -0.12922 -0.0211"/>
    <axis xyz="0 0 -1.0"/>
  </joint>
  <!-- Front Wheel Link -->
  <link name="right_front_wheel">
    <visual>
      <geometry>
        <mesh filename="package://up1_description/meshes/base/wheel_viz.dae" scale="0.001 0.001 0.001"/>
      </geometry>
      <material name="black"/>
    </visual>
    <collision>
      <geometry>
        <mesh filename="package://up1_description/meshes/base/wheel.dae" scale="0.001 0.001 0.001"/>
      </geometry>
    </collision>
    <inertial>
      <mass value="0.01791"/>
      <inertia ixx="0.00000575118" ixy="-0.00000000224" ixz="0.0" iyy="0.00000575882" iyz="0.0" izz="0.0000094354"/>
    </inertial>
  </link>
  <!-- Back Wheel Joint -->
  <joint name="base_to_right_back_wheel" type="continuous">
    <parent link="base_link"/>
    <child link="right_back_wheel"/>
    <origin rpy="1.570795 0 0" xyz="-0.05883 -0.12922 -0.0211"/>
    <axis xyz="0 0 -1.0"/>
  </joint>
  <!-- Back Wheel Link -->
  <link name="right_back_wheel">
    <visual>
      <geometry>
        <mesh filename="package://up1_description/meshes/base/wheel_viz.dae" scale="0.001 0.001 0.001"/>
      </geometry>
      <material name="black"/>
    </visual>
    <collision>
      <geometry>
        <mesh filename="package://up1_description/meshes/base/wheel.dae" scale="0.001 0.001 0.001"/>
      </geometry>
    </collision>
    <inertial>
      <mass value="0.01791"/>
      <inertia ixx="0.00000575118" ixy="-0.00000000224" ixz="0.0" iyy="0.00000575882" iyz="0.0" izz="0.0000094354"/>
    </inertial>
  </link>
  <!-- ============================   Wheel   ============================ -->
  <!-- Front Wheel Joint -->
  <joint name="base_to_left_front_wheel" type="continuous">
    <parent link="base_link"/>
    <child link="left_front_wheel"/>
    <origin rpy="-1.570795 0 0" xyz="0.05569 0.12922 -0.0211"/>
    <axis xyz="0 0 1.0"/>
  </joint>
  <!-- Front Wheel Link -->
  <link name="left_front_wheel">
    <visual>
      <geometry>
        <mesh filename="package://up1_description/meshes/base/wheel_viz.dae" scale="0.001 0.001 0.001"/>
      </geometry>
      <material name="black"/>
    </visual>
    <collision>
      <geometry>
        <mesh filename="package://up1_description/meshes/base/wheel.dae" scale="0.001 0.001 0.001"/>
      </geometry>
    </collision>
    <inertial>
      <mass value="0.01791"/>
      <inertia ixx="0.00000575118" ixy="-0.00000000224" ixz="0.0" iyy="0.00000575882" iyz="0.0" izz="0.0000094354"/>
    </inertial>
  </link>
  <!-- Back Wheel Joint -->
  <joint name="base_to_left_back_wheel" type="continuous">
    <parent link="base_link"/>
    <child link="left_back_wheel"/>
    <origin rpy="-1.570795 0 0" xyz="-0.05883 0.12922 -0.0211"/>
    <axis xyz="0 0 1.0"/>
  </joint>
  <!-- Back Wheel Link -->
  <link name="left_back_wheel">
    <visual>
      <geometry>
        <mesh filename="package://up1_description/meshes/base/wheel_viz.dae" scale="0.001 0.001 0.001"/>
      </geometry>
      <material name="black"/>
    </visual>
    <collision>
      <geometry>
        <mesh filename="package://up1_description/meshes/base/wheel.dae" scale="0.001 0.001 0.001"/>
      </geometry>
    </collision>
    <inertial>
      <mass value="0.01791"/>
      <inertia ixx="0.00000575118" ixy="-0.00000000224" ixz="0.0" iyy="0.00000575882" iyz="0.0" izz="0.0000094354"/>
    </inertial>
  </link>
  <!-- ============================   IO Module   ============================ -->
  <!-- IO Joint -->
  <joint name="base_to_io" type="fixed">
    <parent link="base_link"/>
    <child link="io_link"/>
    <origin xyz="0.09136 0 0.03356"/>
  </joint>
  <!-- IO Link -->
  <link name="io_link">
    <visual>
      <geometry>
        <mesh filename="package://up1_description/meshes/io/io_viz.dae" scale="0.001 0.001 0.001"/>
      </geometry>
      <material name="grey"/>
    </visual>
    <collision>
      <geometry>
        <mesh filename="package://up1_description/meshes/io/io.dae" scale="0.001 0.001 0.001"/>
      </geometry>
    </collision>
    <inertial>
      <mass value="0.09799"/>
      <inertia ixx="0.00036946993" ixy="0.00000010944" ixz="-0.00001523298" iyy="0.00007193675" iyz="0.00000030515" izz="0.00034948153"/>
    </inertial>
  </link>
  <!-- ============================   IO Module Gazebo   ============================ -->
  <gazebo>

    </gazebo>
  <!-- ============================   Camera   ============================ -->
  <!-- Camera Joint -->
  <joint name="io_to_right_camera" type="fixed">
    <parent link="io_link"/>
    <child link="right_camera"/>
    <origin rpy="0 0.209439333333 0" xyz="-0.00619 -0.02127 0.00451"/>
  </joint>
  <!-- Camera Link -->
  <link name="right_camera">
    <visual>
      <geometry>
        <mesh filename="package://up1_description/meshes/io/camera_viz.dae" scale="0.001 0.001 0.001"/>
      </geometry>
      <material name="black"/>
    </visual>
    <collision>
      <geometry>
        <mesh filename="package://up1_description/meshes/io/camera.dae" scale="0.001 0.001 0.001"/>
      </geometry>
    </collision>
    <inertial>
      <mass value="0.00488"/>
      <inertia ixx="0.00000029098" ixy="0.0" ixz="0.0" iyy="0.00000085538" iyz="0.0" izz="0.00000085538"/>
    </inertial>
  </link>
  <!-- ============================   Camera   ============================ -->
  <!-- Camera Joint -->
  <joint name="io_to_left_camera" type="fixed">
    <parent link="io_link"/>
    <child link="left_camera"/>
    <origin rpy="0 0.209439333333 0" xyz="-0.00619 0.02127 0.00451"/>
  </joint>
  <!-- Camera Link -->
  <link name="left_camera">
    <visual>
      <geometry>
        <mesh filename="package://up1_description/meshes/io/camera_viz.dae" scale="0.001 0.001 0.001"/>
      </geometry>
      <material name="black"/>
    </visual>
    <collision>
      <geometry>
        <mesh filename="package://up1_description/meshes/io/camera.dae" scale="0.001 0.001 0.001"/>
      </geometry>
    </collision>
    <inertial>
      <mass value="0.00488"/>
      <inertia ixx="0.00000029098" ixy="0.0" ixz="0.0" iyy="0.00000085538" iyz="0.0" izz="0.00000085538"/>
    </inertial>
  </link>
  <!-- ============================   Dual Arm Module   ============================ -->
  <!-- This xacro group is intended to be used in a full UP1 robot URDF -->
  <!-- Armroot Joint -->
  <joint name="base_to_armroot" type="fixed">
    <parent link="base_link"/>
    <child link="armroot_link"/>
    <origin xyz="-0.00869 0.0 0.03876"/>
  </joint>
  <!-- ============================   Arm Root Link   ============================ -->
  <!-- Armroot Link -->
  <link name="armroot_link">
    <visual>
      <geometry>
        <mesh filename="package://up1_description/meshes/mono_arm/armroot_viz.dae" scale="0.001 0.001 0.001"/>
      </geometry>
      <material name="grey"/>
    </visual>
    <collision>
      <geometry>
        <mesh filename="package://up1_description/meshes/mono_arm/armroot.dae" scale="0.001 0.001 0.001"/>
      </geometry>
    </collision>
    <inertial>
      <mass value="0.20657"/>
      <inertia ixx="0.00096240277" ixy="-0.00000350376" ixz="0.00002354169" iyy="0.00057897825" iyz="0.00000127419" izz="0.00134814249"/>
    </inertial>
  </link>
  <!-- ============================   Arm   ============================ -->
  <!-- Arm Joint 1 -->
  <joint name="right_armroot_to_armlink1" type="revolute">
    <parent link="armroot_link"/>
    <child link="right_armlink1"/>
    <origin rpy="0 3.14159 0" xyz="0.01398 -0.0 0.0402"/>
    <axis xyz="0 0 1"/>
    <limit effort="6.0" lower="-1.570795" upper="1.570795" velocity="5.236"/>
  </joint>
  <!-- Arm Link 1 -->
  <link name="right_armlink1">
    <visual>
      <geometry>
        <mesh filename="package://up1_description/meshes/mono_arm/armlink1_viz.dae" scale="0.001 0.001 0.001"/>
      </geometry>
      <material name="white"/>
    </visual>
    <collision>
      <geometry>
        <mesh filename="package://up1_description/meshes/mono_arm/armlink1.dae" scale="0.001 0.001 0.001"/>
      </geometry>
    </collision>
    <inertial>
      <mass value="0.06985"/>
      <inertia ixx="0.00023448766" ixy="0.0000000027" ixz="0.00000001913" iyy="0.00024004726" iyz="-0.0000015393" izz="0.00007431363"/>
    </inertial>
  </link>
  <!-- Arm Joint 2 -->
  <joint name="right_armlink1_to_armlink2" type="revolute">
    <parent link="right_armlink1"/>
    <child link="right_armlink2"/>
    <origin rpy="1.570795 3.14159 0" xyz="0 0 -0.0553"/>
    <axis xyz="0 0 1.0"/>
    <limit effort="6.0" lower="-1.570795" upper="1.570795" velocity="4.553"/>
  </joint>
  <!-- Arm Link 2 -->
  <link name="right_armlink2">
    <visual>
      <geometry>
        <mesh filename="package://up1_description/meshes/mono_arm/armlink2_viz.dae" scale="0.001 0.001 0.001"/>
      </geometry>
      <material name="white"/>
    </visual>
    <collision>
      <geometry>
        <mesh filename="package://up1_description/meshes/mono_arm/armlink2.dae" scale="0.001 0.001 0.001"/>
      </geometry>
    </collision>
    <inertial>
      <mass value="0.07067"/>
      <inertia ixx="0.00029708797" ixy="-0.00000000444" ixz="0.00000000068" iyy="0.0000799845" iyz="-0.00000174097" izz="0.00026073683"/>
    </inertial>
  </link>
  <!-- Arm Joint 3 -->
  <joint name="right_armlink2_to_armlink3" type="revolute">
    <parent link="right_armlink2"/>
    <child link="right_armlink3"/>
    <origin rpy="-1.570795 3.14159 0" xyz="0 0.09602 0"/>
    <axis xyz="0 0 -1"/>
    <limit effort="6.0" lower="-1.570795" upper="1.570795" velocity="5.236"/>
  </joint>
  <!-- Arm Link 3 -->
  <link name="right_armlink3">
    <visual>
      <geometry>
        <mesh filename="package://up1_description/meshes/mono_arm/armlink3_viz.dae" scale="0.001 0.001 0.001"/>
      </geometry>
      <material name="white"/>
    </visual>
    <collision>
      <geometry>
        <mesh filename="package://up1_description/meshes/mono_arm/armlink3.dae" scale="0.001 0.001 0.001"/>
      </geometry>
    </collision>
    <inertial>
      <mass value="0.04828"/>
      <inertia ixx="0.00010408822" ixy="0.00000002684" ixz="0.00000006554" iyy="0.00008358122" iyz="0.00000001571" izz="0.00004453887"/>
    </inertial>
  </link>
  <!-- Arm Joint 4 -->
  <joint name="right_armlink3_to_armlink4" type="revolute">
    <parent link="right_armlink3"/>
    <child link="right_armlink4"/>
    <origin rpy="1.570795 0 0" xyz="0 0 0.05588"/>
    <axis xyz="0 0 1.0"/>
    <limit effort="6.0" lower="-1.570795" upper="1.570795" velocity="5.236"/>
  </joint>
  <!-- Arm Link 4 -->
  <link name="right_armlink4">
    <visual>
      <geometry>
        <mesh filename="package://up1_description/meshes/mono_arm/armlink4_viz.dae" scale="0.001 0.001 0.001"/>
      </geometry>
      <material name="white"/>
    </visual>
    <collision>
      <geometry>
        <mesh filename="package://up1_description/meshes/mono_arm/armlink4.dae" scale="0.001 0.001 0.001"/>
      </geometry>
    </collision>
    <inertial>
      <mass value="0.07021"/>
      <inertia ixx="0.00022365714" ixy="0.00000581335" ixz="-0.00000002583" iyy="0.00004497277" iyz="0.00000036702" izz="0.00022294807"/>
    </inertial>
  </link>
  <!-- Arm Joint 5 -->
  <joint name="right_armlink4_to_gripper" type="revolute">
    <parent link="right_armlink4"/>
    <child link="right_gripper"/>
    <origin rpy="0 1.570795 0" xyz="0 0.07641 0"/>
    <axis xyz="0 0 -1.0"/>
    <limit effort="6.0" lower="-1.570795" upper="1.570795" velocity="5.236"/>
  </joint>
  <!-- Gripper Link -->
  <link name="right_gripper">
    <visual>
      <geometry>
        <mesh filename="package://up1_description/meshes/mono_arm/armlink5_viz.dae" scale="0.001 0.001 0.001"/>
      </geometry>
      <material name="white"/>
    </visual>
    <collision>
      <geometry>
        <mesh filename="package://up1_description/meshes/mono_arm/armlink5.dae" scale="0.001 0.001 0.001"/>
      </geometry>
    </collision>
    <inertial>
      <mass value="0.07134"/>
      <inertia ixx="0.00024486788" ixy="-0.00000179765" ixz="-0.0000013121" iyy="0.00007141374" iyz="0.00000015595" izz="0.0002397239"/>
    </inertial>
  </link>
  <!-- ============================   Arm Gazebo  ============================ -->
  <gazebo reference="right_armlink1">
    <turnGravityOff>true</turnGravityOff>
  </gazebo>
  <gazebo reference="right_armlink2">
    <turnGravityOff>true</turnGravityOff>
  </gazebo>
  <gazebo reference="right_armlink3">
    <turnGravityOff>true</turnGravityOff>
  </gazebo>
  <gazebo reference="right_armlink4">
    <turnGravityOff>true</turnGravityOff>
  </gazebo>
  <gazebo reference="right_gripper">
    <turnGravityOff>true</turnGravityOff>
  </gazebo>
  <!-- ============================   Arm Transmission  ============================ -->
  <transmission name="right_armroot_to_armlink1_trans">
    <type>transmission_interface/SimpleTransmission</type>
    <joint name="right_armroot_to_armlink1">
      <hardwareInterface>PositionJointInterface</hardwareInterface>
    </joint>
    <actuator name="right_armroot_to_armlink1_motor">
      <mechanicalReduction>1</mechanicalReduction>
    </actuator>
  </transmission>
  <transmission name="right_armlink1_to_armlink2_trans">
    <type>transmission_interface/SimpleTransmission</type>
    <joint name="right_armlink1_to_armlink2">
      <hardwareInterface>PositionJointInterface</hardwareInterface>
    </joint>
    <actuator name="right_armlink1_to_armlink2_motor">
      <mechanicalReduction>1</mechanicalReduction>
    </actuator>
  </transmission>
  <transmission name="right_armlink2_to_armlink3_trans">
    <type>transmission_interface/SimpleTransmission</type>
    <joint name="right_armlink2_to_armlink3">
      <hardwareInterface>PositionJointInterface</hardwareInterface>
    </joint>
    <actuator name="right_armlink2_to_armlink3_motor">
      <mechanicalReduction>1</mechanicalReduction>
    </actuator>
  </transmission>
  <transmission name="right_armlink3_to_armlink4_trans">
    <type>transmission_interface/SimpleTransmission</type>
    <joint name="right_armlink3_to_armlink4">
      <hardwareInterface>PositionJointInterface</hardwareInterface>
    </joint>
    <actuator name="right_armlink3_to_armlink4_motor">
      <mechanicalReduction>1</mechanicalReduction>
    </actuator>
  </transmission>
  <transmission name="right_armlink4_to_gripper_trans">
    <type>transmission_interface/SimpleTransmission</type>
    <joint name="right_armlink4_to_gripper">
      <hardwareInterface>PositionJointInterface</hardwareInterface>
    </joint>
    <actuator name="right_armlink4_to_gripper_motor">
      <mechanicalReduction>1</mechanicalReduction>
    </actuator>
  </transmission>
  <!-- ============================   Gripper   ============================ -->
  <!-- Finger Joint 1 -->
  <joint name="right_finger_joint" type="prismatic">
    <parent link="right_gripper"/>
    <child link="right_finger1"/>
    <origin rpy="0 1.570795 0" xyz="-0.018 0.08121 0"/>
    <axis xyz="0 0 1"/>
    <limit effort="6.0" lower="0" upper="0.018" velocity="1"/>
  </joint>
  <!-- Finger Link 1 -->
  <link name="right_finger1">
    <visual>
      <geometry>
        <mesh filename="package://up1_description/meshes/mono_arm/finger_viz.dae" scale="0.001 0.001 0.001"/>
      </geometry>
      <material name="grey"/>
    </visual>
    <collision>
      <geometry>
        <mesh filename="package://up1_description/meshes/mono_arm/finger.dae" scale="0.001 0.001 0.001"/>
      </geometry>
    </collision>
    <inertial>
      <mass value="0.01174"/>
      <inertia ixx="0.00000285949" ixy="-0.00000001641" ixz="0.00000001803" iyy="0.00000203198" iyz="-0.00000077289" izz="0.00000299021"/>
    </inertial>
  </link>
  <!-- Finger Joint 2 -->
  <joint name="right_finger_joint_fake" type="prismatic">
    <parent link="right_gripper"/>
    <child link="right_finger2"/>
    <origin rpy="0 -1.570795 0" xyz="0.018 0.08121 0"/>
    <axis xyz="0 0 1"/>
    <limit effort="6.0" lower="0" upper="0.018" velocity="1"/>
    <mimic joint="right_finger_joint" multiplier="1" offset="0"/>
  </joint>
  <!-- Finger Link 2 -->
  <link name="right_finger2">
    <visual>
      <geometry>
        <mesh filename="package://up1_description/meshes/mono_arm/finger_viz.dae" scale="0.001 0.001 0.001"/>
      </geometry>
      <material name="grey"/>
    </visual>
    <collision>
      <geometry>
        <mesh filename="package://up1_description/meshes/mono_arm/finger.dae" scale="0.001 0.001 0.001"/>
      </geometry>
    </collision>
    <inertial>
      <mass value="0.01174"/>
      <inertia ixx="0.00000285949" ixy="-0.00000001641" ixz="0.00000001803" iyy="0.00000203198" iyz="-0.00000077289" izz="0.00000299021"/>
    </inertial>
  </link>
  <!-- ============================   Gripper Gazebo   ============================ -->
  <gazebo reference="right_finger1">
    <turnGravityOff>true</turnGravityOff>
  </gazebo>
  <gazebo reference="right_finger2">
    <turnGravityOff>true</turnGravityOff>
  </gazebo>
  <!-- ============================   Gripper Transmission   ============================ -->
  <transmission name="right_gripper_trans">
    <type>transmission_interface/SimpleTransmission</type>
    <joint name="right_finger_joint">
      <hardwareInterface>PositionJointInterface</hardwareInterface>
    </joint>
    <actuator name="right_gripper_motor">
      <mechanicalReduction>1</mechanicalReduction>
    </actuator>
  </transmission>
  <transmission name="right_gripper_trans">
    <type>transmission_interface/SimpleTransmission</type>
    <joint name="right_finger_joint_fake">
      <hardwareInterface>PositionJointInterface</hardwareInterface>
    </joint>
    <actuator name="right_gripper_motor">
      <mechanicalReduction>1</mechanicalReduction>
    </actuator>
  </transmission>
</robot>

